Workbook

Sheet Respostas ao formulário 1
A1: Carimbo de data/hora | B1: Pergunta sem título

Sheet Stakeholders
A1: Região | B1: =SUM(B2:B872) -> 8.0796891 | C1: País | D1: =SUM(D2:D872) -> 55.520166 | E1: Instituição | F1: # stakeholders | G1: Órgão Associado | H1: Link | I1: Observações | J1: Relatórios por instituição | K1: Chave | L1: ID Único Base Projeto OTAN
A2: África | B2: =1/(COUNTIF($A$2:$A$310,A2)) -> 0.5 | C2: África do Sul | D2: =IF(C2="Não se aplica",0,1/(COUNTIF($C$2:$C$310,C2))) -> 1 | E2: Institute for Security Studies (ISS) | F2: =IF(E2="",0,1) -> 1 | H2: https://issafrica.org/ | J2: =COUNTIF(Relatórios!F:F,E2) -> 25 | K2: 1
A3: América do Norte | B3: =1/(COUNTIF($A$2:$A$310,A3)) -> 0.015625 | C3: EUA | D3: =IF(C3="Não se aplica",0,1/(COUNTIF($C$2:$C$310,C3))) -> 0.017857143 | E3: United States African Command (AFRICOM) | F3: =IF(E3="",0,1) -> 1 | H3: https://www.africom.mil/ | J3: =COUNTIF(Relatórios!F:F,E3) -> 1 | K3: 2
A4: Organismo Internacional | B4: =1/(COUNTIF($A$2:$A$310,A4)) -> 0.055555556 | C4: União Europeia | D4: =IF(C4="Não se aplica",0,1/(COUNTIF($C$2:$C$310,C4))) -> 0.14285714 | E4: European Parliament (EUROPARL) | F4: =IF(E4="",0,1) -> 1 | H4: https://www.europarl.europa.eu/portal/en | J4: =COUNTIF(Relatórios!F:F,E4) -> 1 | K4: 3
A5: Europa | B5: =1/(COUNTIF($A$2:$A$310,A5)) -> 0.011494253 | C5: França | D5: =IF(C5="Não se aplica",0,1/(COUNTIF($C$2:$C$310,C5))) -> 0.2 | E5: Report Linker | F5: =IF(E5="",0,1) -> 1 | H5: https://www.reportlinker.com/ | J5: =COUNTIF(Relatórios!F:F,E5) -> 1 | K5: 4
A6: Organismo Internacional | B6: =1/(COUNTIF($A$2:$A$310,A6)) -> 0.055555556 | C6: United Nations Peacekeeping | D6: =IF(C6="Não se aplica",0,1/(COUNTIF($C$2:$C$310,C6))) -> 1 | E6: United Nations Peacekeeping | F6: =IF(E6="",0,1) -> 1 | H6: https://peacekeeping.un.org/en | J6: =COUNTIF(Relatórios!F:F,E6) -> 5 | K6: 5
A7: América Central | B7: =1/(COUNTIF($A$2:$A$310,A7)) -> 0.5 | C7: Honduras | D7: =IF(C7="Não se aplica",0,1/(COUNTIF($C$2:$C$310,C7))) -> 1 | E7: Facultad de Ciencias Espaciales | F7: =IF(E7="",0,1) -> 1 | H7: https://cienciasespaciales.unah.edu.hn/ | J7: =COUNTIF(Relatórios!F:F,E7) -> 1 | K7: 6
A8: América Central | B8: =1/(COUNTIF($A$2:$A$310,A8)) -> 0.5 | C8: Jamaica | D8: =IF(C8="Não se aplica",0,1/(COUNTIF($C$2:$C$310,C8))) -> 1 | E8: Planning Institute of Jamaica | F8: =IF(E8="",0,1) -> 1 | H8: https://www.pioj.gov.jm/ | I8: Com a implementação da visão Jamaica 2030, desenvolveu-se o plano de metas do desenvolvimento sustentável que utiliza a estratégia de ROAD MAP para apresentar as estratégias. | J8: =COUNTIF(Relatórios!F:F,E8) -> 0 | K8: 7
A9: América do Norte | B9: =1/(COUNTIF($A$2:$A$310,A9)) -> 0.015625 | C9: Canadá | D9: =IF(C9="Não se aplica",0,1/(COUNTIF($C$2:$C$310,C9))) -> 0.11111111 | E9: Defense and Security Foresight Group | F9: =IF(E9="",0,1) -> 1 | G9: University of Waterloo | H9: https://uwaterloo.ca/defence-security-foresight-group/ | I9: É um grupo de pesquisa vinculado a faculdade que pesquisa sobre o assunto. | J9: =COUNTIF(Relatórios!F:F,E9) -> 0 | K9: 8
A10: América do Norte | B10: =1/(COUNTIF($A$2:$A$310,A10)) -> 0.015625 | C10: Canadá | D10: =IF(C10="Não se aplica",0,1/(COUNTIF($C$2:$C$310,C10))) -> 0.11111111 | E10: Centre for the Study of Security and Development | F10: =IF(E10="",0,1) -> 1 | G10: Dalhousie University | H10: https://www.dal.ca/sites/cssd.html | I10: É um grupo de pesquisa vinculado a faculdade que pesquisa sobre o assunto. | J10: =COUNTIF(Relatórios!F:F,E10) -> 0 | K10: 9
A11: América do Norte | B11: =1/(COUNTIF($A$2:$A$310,A11)) -> 0.015625 | C11: Canadá | D11: =IF(C11="Não se aplica",0,1/(COUNTIF($C$2:$C$310,C11))) -> 0.11111111 | E11: Canadian Network for Defence and Security Analysis | F11: =IF(E11="",0,1) -> 1 | G11: Basileia School of International Affairs | H11: https://www.balsillieschool.ca/research/cndsa/ | I11: https://www.balsillieschool.ca/wp-content/uploads/2019/02/CNDSA-Report-2019.pdf | J11: =COUNTIF(Relatórios!F:F,E11) -> 1 | K11: 10
A12: América do Norte | B12: =1/(COUNTIF($A$2:$A$310,A12)) -> 0.015625 | C12: Canadá | D12: =IF(C12="Não se aplica",0,1/(COUNTIF($C$2:$C$310,C12))) -> 0.11111111 | E12: North American and Arctic Defence and Security Network | F12: =IF(E12="",0,1) -> 1 | G12: Trent University | H12: https://www.naadsn.ca/ | I12: https://www.naadsn.ca/wp-content/uploads/2020/09/20-Sept-15-NAADSN-Canadian-Arctic-Security-Strategic-Foresight-Analysis-2020-DRAFT-FOR-DISCUSSION-2.pdf | J12: =COUNTIF(Relatórios!F:F,E12) -> 5 | K12: 11
A13: América do Norte | B13: =1/(COUNTIF($A$2:$A$310,A13)) -> 0.015625 | C13: Canadá | D13: =IF(C13="Não se aplica",0,1/(COUNTIF($C$2:$C$310,C13))) -> 0.11111111 | E13: Canadian Army | F13: =IF(E13="",0,1) -> 1 | G13: Government of Canada | H13: http://www.army-armee.forces.gc.ca/en/index.page | J13: =COUNTIF(Relatórios!F:F,E13) -> 1 | K13: 12
A14: América do Norte | B14: =1/(COUNTIF($A$2:$A$310,A14)) -> 0.015625 | C14: Canadá | D14: =IF(C14="Não se aplica",0,1/(COUNTIF($C$2:$C$310,C14))) -> 0.11111111 | E14: Policy Horizons Canada | F14: =IF(E14="",0,1) -> 1 | G14: Government of Canada | H14: https://horizons.gc.ca/en/home/ | J14: =COUNTIF(Relatórios!F:F,E14) -> 1 | K14: 13
A15: América do Norte | B15: =1/(COUNTIF($A$2:$A$310,A15)) -> 0.015625 | C15: EUA | D15: =IF(C15="Não se aplica",0,1/(COUNTIF($C$2:$C$310,C15))) -> 0.017857143 | E15: International Institute of Forecasters | F15: =IF(E15="",0,1) -> 1 | H15: https://forecasters.org/ | J15: =COUNTIF(Relatórios!F:F,E15) -> 0 | K15: 14
A16: América do Norte | B16: =1/(COUNTIF($A$2:$A$310,A16)) -> 0.015625 | C16: EUA | D16: =IF(C16="Não se aplica",0,1/(COUNTIF($C$2:$C$310,C16))) -> 0.017857143 | E16: Center for Global Development | F16: =IF(E16="",0,1) -> 1 | H16: https://www.cgdev.org/ | J16: =COUNTIF(Relatórios!F:F,E16) -> 1 | K16: 15
A17: América do Norte | B17: =1/(COUNTIF($A$2:$A$310,A17)) -> 0.015625 | C17: EUA | D17: =IF(C17="Não se aplica",0,1/(COUNTIF($C$2:$C$310,C17))) -> 0.017857143 | E17: German Marshal Fund | F17: =IF(E17="",0,1) -> 1 | H17: https://www.gmfus.org/ | I17: A GMF é uma instituição com parcetias transatlântica. Apesar de a matriz ser em Washington DC, trabalha em conjunto com países Europeus | J17: =COUNTIF(Relatórios!F:F,E17) -> 0 | K17: 16
A18: América do Norte | B18: =1/(COUNTIF($A$2:$A$310,A18)) -> 0.015625 | C18: EUA | D18: =IF(C18="Não se aplica",0,1/(COUNTIF($C$2:$C$310,C18))) -> 0.017857143 | E18: Center for Strategic & International Studies (CSIS) | F18: =IF(E18="",0,1) -> 1 | H18: https://www.csis.org/ | I18: ir na seção "Programs" | J18: =COUNTIF(Relatórios!F:F,E18) -> 5 | K18: 17
A19: América do Norte | B19: =1/(COUNTIF($A$2:$A$310,A19)) -> 0.015625 | C19: EUA | D19: =IF(C19="Não se aplica",0,1/(COUNTIF($C$2:$C$310,C19))) -> 0.017857143 | E19: Global Risk Intel | F19: =IF(E19="",0,1) -> 1 | H19: https://www.globalriskintel.com/ | J19: =COUNTIF(Relatórios!F:F,E19) -> 1 | K19: 18
A20: América do Norte | B20: =1/(COUNTIF($A$2:$A$310,A20)) -> 0.015625 | C20: EUA | D20: =IF(C20="Não se aplica",0,1/(COUNTIF($C$2:$C$310,C20))) -> 0.017857143 | E20: Air Force Warfighting Integration Capability | F20: =IF(E20="",0,1) -> 1 | G20: United States Air Force | H20: https://www.afwic.af.mil/ | J20: =COUNTIF(Relatórios!F:F,E20) -> 1 | K20: 19
A21: América do Norte | B21: =1/(COUNTIF($A$2:$A$310,A21)) -> 0.015625 | C21: EUA | D21: =IF(C21="Não se aplica",0,1/(COUNTIF($C$2:$C$310,C21))) -> 0.017857143 | E21: RAND Corporation | F21: =IF(E21="",0,1) -> 1 | H21: https://www.rand.org/ | J21: =COUNTIF(Relatórios!F:F,E21) -> 25 | K21: 20
A22: América do Norte | B22: =1/(COUNTIF($A$2:$A$310,A22)) -> 0.015625 | C22: EUA | D22: =IF(C22="Não se aplica",0,1/(COUNTIF($C$2:$C$310,C22))) -> 0.017857143 | E22: National Intelligence Council | F22: =IF(E22="",0,1) -> 1 | G22: OFFICE of the DIRECTOR of NATIONAL INTELLIGENCE | H22: https://www.dni.gov/index.php | J22: =COUNTIF(Relatórios!F:F,E22) -> 1 | K22: 21
A23: América do Norte | B23: =1/(COUNTIF($A$2:$A$310,A23)) -> 0.015625 | C23: EUA | D23: =IF(C23="Não se aplica",0,1/(COUNTIF($C$2:$C$310,C23))) -> 0.017857143 | E23: National Counterproliferation Center (NCPC) | F23: =IF(E23="",0,1) -> 1 | G23: OFFICE of the DIRECTOR of NATIONAL INTELLIGENCE | H23: https://www.dni.gov/index.php/ncpc-home | J23: =COUNTIF(Relatórios!F:F,E23) -> 0 | K23: 22
A24: América do Norte | B24: =1/(COUNTIF($A$2:$A$310,A24)) -> 0.015625 | C24: EUA | D24: =IF(C24="Não se aplica",0,1/(COUNTIF($C$2:$C$310,C24))) -> 0.017857143 | E24: National Counterintelligence and Security Center (NCSC) | F24: =IF(E24="",0,1) -> 1 | G24: OFFICE of the DIRECTOR of NATIONAL INTELLIGENCE | H24: https://www.dni.gov/index.php/ncsc-home | J24: =COUNTIF(Relatórios!F:F,E24) -> 0 | K24: 23
A25: América do Norte | B25: =1/(COUNTIF($A$2:$A$310,A25)) -> 0.015625 | C25: EUA | D25: =IF(C25="Não se aplica",0,1/(COUNTIF($C$2:$C$310,C25))) -> 0.017857143 | E25: National Counterterrorism Center (NCTC) | F25: =IF(E25="",0,1) -> 1 | G25: OFFICE of the DIRECTOR of NATIONAL INTELLIGENCE | H25: https://www.dni.gov/index.php/nctc-home | J25: =COUNTIF(Relatórios!F:F,E25) -> 0 | K25: 24
A26: América do Norte | B26: =1/(COUNTIF($A$2:$A$310,A26)) -> 0.015625 | C26: EUA | D26: =IF(C26="Não se aplica",0,1/(COUNTIF($C$2:$C$310,C26))) -> 0.017857143 | E26: Institute for the Future | F26: =IF(E26="",0,1) -> 1 | H26: https://www.iftf.org/home/ | I26: Não encontrei um relatório anual sobre segurança, mas há alguns tópicos sobre estudos do futuro. | J26: =COUNTIF(Relatórios!F:F,E26) -> 0 | K26: 25
A27: América do Norte | B27: =1/(COUNTIF($A$2:$A$310,A27)) -> 0.015625 | C27: EUA | D27: =IF(C27="Não se aplica",0,1/(COUNTIF($C$2:$C$310,C27))) -> 0.017857143 | E27: House Armed Service Committee | F27: =IF(E27="",0,1) -> 1 | H27: https://armedservices.house.gov/2020/9/future-of-defense-task-force-releases-final-report | I27: https://armedservices.house.gov/_cache/files/2/6/26129500-d208-47ba-a9f7-25a8f82828b0/424EB2008281A3C79BA8C7EA71890AE9.future-of-defense-task-force-report.pdf | J27: =COUNTIF(Relatórios!F:F,E27) -> 1 | K27: 26
A28: América do Norte | B28: =1/(COUNTIF($A$2:$A$310,A28)) -> 0.015625 | C28: EUA | D28: =IF(C28="Não se aplica",0,1/(COUNTIF($C$2:$C$310,C28))) -> 0.017857143 | E28: All Partner Access Network | F28: =IF(E28="",0,1) -> 1 | H28: https://www.apan.org/ | J28: =COUNTIF(Relatórios!F:F,E28) -> 1 | K28: 27
A29: América do Norte | B29: =1/(COUNTIF($A$2:$A$310,A29)) -> 0.015625 | C29: EUA | D29: =IF(C29="Não se aplica",0,1/(COUNTIF($C$2:$C$310,C29))) -> 0.017857143 | E29: Middle East Institute | F29: =IF(E29="",0,1) -> 1 | H29: https://www.mei.edu/programs/strategic-foresight-initiative | I29: É um Think Tank focado na região do Oriente Médio, tendo algumas publicações sobre o tema. | J29: =COUNTIF(Relatórios!F:F,E29) -> 2 | K29: 28
A30: América do Norte | B30: =1/(COUNTIF($A$2:$A$310,A30)) -> 0.015625 | C30: EUA | D30: =IF(C30="Não se aplica",0,1/(COUNTIF($C$2:$C$310,C30))) -> 0.017857143 | E30: Futures and Concepts Center | F30: =IF(E30="",0,1) -> 1 | G30: United States Army | H30: https://www.army.mil/FuturesandConceptsCenter | I30: FCC develops concepts, determines requirements, conducts experimentation, and begins integration of the future force to ensure the Army wins in 2035 and beyond. Contact: USARMY.JBLE.AFC-FCC.MBX.FCC-PAO-Media@mail.mil | J30: =COUNTIF(Relatórios!F:F,E30) -> 0 | K30: 29
A31: América do Norte | B31: =1/(COUNTIF($A$2:$A$310,A31)) -> 0.015625 | C31: EUA | D31: =IF(C31="Não se aplica",0,1/(COUNTIF($C$2:$C$310,C31))) -> 0.017857143 | E31: The brookings Africa Growth Initiative | F31: =IF(E31="",0,1) -> 1 | G31: The brookings | H31: https://www.brookings.edu/series/foresight-africa/ | I31: "The Foresight Africa project is a series of reports, commentaries and events that aim to help policymakers and Africa watchers stay ahead of the trends and developments impacting the continent. Since 2011, the Brookings Africa Growth Initiative has used the occasion of the new year to assess Africa’s top priorities for the year." | J31: =COUNTIF(Relatórios!F:F,E31) -> 4 | K31: 30
A32: América do Norte | B32: =1/(COUNTIF($A$2:$A$310,A32)) -> 0.015625 | C32: EUA | D32: =IF(C32="Não se aplica",0,1/(COUNTIF($C$2:$C$310,C32))) -> 0.017857143 | E32: The brookings | F32: =IF(E32="",0,1) -> 1 | H32: https://www.brookings.edu | J32: =COUNTIF(Relatórios!F:F,E32) -> 4 | K32: 31
A33: América do Norte | B33: =1/(COUNTIF($A$2:$A$310,A33)) -> 0.015625 | C33: EUA | D33: =IF(C33="Não se aplica",0,1/(COUNTIF($C$2:$C$310,C33))) -> 0.017857143 | E33: Atlantic Council | F33: =IF(E33="",0,1) -> 1 | H33: https://www.atlanticcouncil.org/ | I33: O Atlantic Council tem programas especializados em estudar regiões específicas do globo. destaque para o programa "Foresight, Strategy, and Risks Initiative" e "Scowcroft Center for Strategy and Security" | J33: =COUNTIF(Relatórios!F:F,E33) -> 6 | K33: 32
A34: América do Norte | B34: =1/(COUNTIF($A$2:$A$310,A34)) -> 0.015625 | C34: EUA | D34: =IF(C34="Não se aplica",0,1/(COUNTIF($C$2:$C$310,C34))) -> 0.017857143 | E34: Federal Emergency Management Agency | F34: =IF(E34="",0,1) -> 1 | H34: https://www.fema.gov/pt-br | J34: =COUNTIF(Relatórios!F:F,E34) -> 1 | K34: 33
A35: América do Norte | B35: =1/(COUNTIF($A$2:$A$310,A35)) -> 0.015625 | C35: EUA | D35: =IF(C35="Não se aplica",0,1/(COUNTIF($C$2:$C$310,C35))) -> 0.017857143 | E35: Center for Strategic and Budgetary Assessments | F35: =IF(E35="",0,1) -> 1 | H35: https://csbaonline.org/ | J35: =COUNTIF(Relatórios!F:F,E35) -> 1 | K35: 34
A36: América do Norte | B36: =1/(COUNTIF($A$2:$A$310,A36)) -> 0.015625 | C36: México | D36: =IF(C36="Não se aplica",0,1/(COUNTIF($C$2:$C$310,C36))) -> 1 | E36: Revista del Centro de Estudios Superiores Navales | F36: =IF(E36="",0,1) -> 1 | G36: Centro de Estudios Superiores Navales | H36: https://biblat.unam.mx/pt/revista/revista-del-centro-de-estudios-superiores-navales | J36: =COUNTIF(Relatórios!F:F,E36) -> 2 | K36: 35
A37: América do Norte | B37: =1/(COUNTIF($A$2:$A$310,A37)) -> 0.015625 | C37: EUA | D37: =IF(C37="Não se aplica",0,1/(COUNTIF($C$2:$C$310,C37))) -> 0.017857143 | E37: Mad Scientist Laboratory | F37: =IF(E37="",0,1) -> 1 | G37: United States Army | H37: https://madsciblog.tradoc.army.mil/ | I37: Iniciativa do exército norte-americano - uma comunidade de exploração contínua através de parcerias colaborativas e diálogo com academia, indústria e governo. | J37: =COUNTIF(Relatórios!F:F,E37) -> 0 | K37: 36
A38: América do Norte | B38: =1/(COUNTIF($A$2:$A$310,A38)) -> 0.015625 | C38: EUA | D38: =IF(C38="Não se aplica",0,1/(COUNTIF($C$2:$C$310,C38))) -> 0.017857143 | E38: PriceWaterHouseCoopers (PwC) | F38: =IF(E38="",0,1) -> 1 | H38: https://www.pwc.com/gx/en/ceo-agenda/ceosurvey/2020/trends/defence.html | I38: Consultoria global com enfoque especializado em defesa. | J38: =COUNTIF(Relatórios!F:F,E38) -> 1 | K38: 37
A39: América do Norte | B39: =1/(COUNTIF($A$2:$A$310,A39)) -> 0.015625 | C39: EUA | D39: =IF(C39="Não se aplica",0,1/(COUNTIF($C$2:$C$310,C39))) -> 0.017857143 | E39: The Heritage Foundation | F39: =IF(E39="",0,1) -> 1 | H39: https://www.heritage.org/defense | I39: OSC que aborda temas de cibersegurança, política espacial, tecnologia, defesa, segurança nacional, terrorismo, imigração, energia, com vistas à proteção dos princípios norte-americanos. | J39: =COUNTIF(Relatórios!F:F,E39) -> 1 | K39: 38
A40: América do Norte | B40: =1/(COUNTIF($A$2:$A$310,A40)) -> 0.015625 | C40: EUA | D40: =IF(C40="Não se aplica",0,1/(COUNTIF($C$2:$C$310,C40))) -> 0.017857143 | E40: Deloitte | F40: =IF(E40="",0,1) -> 1 | G40: Defense and National Security | H40: https://www2.deloitte.com/global/en/pages/public-sector/articles/gx-national-security-industry-outlook.html | I40: Grupo de trabalho da consultoria global, neste caso representada por seu head regional especializado em defesa e segurança nacional, Nathan Houser. | J40: =COUNTIF(Relatórios!F:F,E40) -> 0 | K40: 39
...

Sheet Relatórios
A1: Ano | B1: Região | C1: País Solicitante | D1: País Objeto | E1: País / Org. Int. | F1: Instituição | G1: Check instituição | H1: Nome do Estudo | I1: Link | J1: Trata de def/seg | K1: Sementes | L1: Político/geopolítico | M1: Econômico | N1: Social | O1: Tecnológico | P1: Ambiental | Q1: Legal | R1: Militar | S1: Marítimo | T1: Terrestre | U1: Aeroespacial | V1: Macrotema? | W1: Método | X1: Palavra Chave 1 | Y1: Palavra Chave 2 | Z1: Palavra Chave 3 | AA1: Observações | AB1: Inserido por | AC1: inserido em | AD1: Chave Relatório | AE1: Chave_Instituicao | AF1: Chave_Pais | AG1: Indicação grupo LCS? | AH1: Ciclo de Atualizacao | AK1: Email do Responsável | AL1: Data de Atualização
A2: 2020 | B2: Organismo Internacional | C2: Comissão Europeia | D2: Europa | E2: União Europeia | F2: Comissão Europeia | G2: =COUNTIF(Stakeholders!$E$2:$E960,F2) -> 1 | H2: 2020 strategic foresight report | I2: https://ec.europa.eu/info/sites/info/files/strategic_foresight_report_2020_1.pdf | J2: sim | K2: sim | L2: sim | M2: sim | N2: sim | O2: sim | P2: sim | Q2: sim | R2: sim | S2: sim | T2: sim | U2: sim | V2: Globalização político-jurídica | W2: sim | X2: Cooperação transnacional interblocos | Y2: Resiliência em bloco | Z2: Monitoramento integrado | AB2: Vj | AC2: 44315 | AD2: 1 | AE2: =VLOOKUP(F2,Stakeholders!E:K,7,0) -> 58 | AF2: =VLOOKUP(B2&D2,Areas!$D:$E,2,FALSE) -> #N/A | AH2: 1 - Projeto Prospecta Parte 02 - 2022 | AI2: =COUNTIF(Stakeholders!$E$2:$E$114,F2) -> 1
A3: 2018 | B3: América do Norte | C3: EUA | D3: Global | E3: EUA | F3: Global Risk Intel | G3: =COUNTIF(Stakeholders!$E$2:$E960,F3) -> 1 | H3: Forecasting Future Space Risks: Environmental, commercial, and military aspects | I3: https://www.globalriskintel.com/reports/forecasting-future-space-risks-environmental-commercial-and-military-aspects | J3: sim | K3: sim | M3: sim | P3: sim | R3: sim | U3: sim | W3: não | AB3: Yasmim | AD3: 2 | AE3: =VLOOKUP(F3,Stakeholders!E:K,7,0) -> 18 | AF3: =VLOOKUP(B3&D3,Areas!$D:$E,2,FALSE) -> 283 | AH3: 1 - Projeto Prospecta Parte 02 - 2022 | AI3: =COUNTIF(Stakeholders!$E$2:$E$114,F3) -> 1
A4: 2020 | B4: América do Norte | C4: Canadá | D4: Região do Ártico | E4: Canadá | F4: North American and Arctic Defence and Security Network | G4: =COUNTIF(Stakeholders!$E$2:$E960,F4) -> 1 | H4: Understanding The Future Arctic Security Environment; Applying NATO Strategic Foresight Analysis to Canadian Arctic Defense and Security | I4: https://www.naadsn.ca/wp-content/uploads/2020/09/20-Sept-15-NAADSN-Canadian-Arctic-Security-Strategic-Foresight-Analysis-2020-DRAFT-FOR-DISCUSSION-2.pdf | J4: sim | K4: não | W4: sim | AA4: O relatório possui uma parte sobre a metodologia usada, como também da estratégia que a NATO utiliza para fazer análises. | AB4: Yasmim | AD4: 3 | AE4: =VLOOKUP(F4,Stakeholders!E:K,7,0) -> 11 | AF4: =VLOOKUP(B4&D4,Areas!$D:$E,2,FALSE) -> #N/A | AH4: 1 - Projeto Prospecta Parte 02 - 2022 | AI4: =COUNTIF(Stakeholders!$E$2:$E$114,F4) -> 1
A5: 2021 | B5: América do Norte | C5: EUA | D5: Oriente Médio | E5: EUA | F5: RAND Corporation | G5: =COUNTIF(Stakeholders!$E$2:$E960,F5) -> 1 | H5: Reimagining U.S. Strategy in the Middle East: Sustainable Partnerships, Strategic Investiments | I5: https://www.rand.org/pubs/research_reports/RRA958-2.html | J5: sim | K5: sim | L5: sim | M5: sim | N5: sim | O5: sim | P5: não | Q5: não | R5: sim | S5: não | T5: sim | U5: não | W5: não | X5: Política estratégica dos EUA | Y5: Oriente Médio | Z5: Liderança Internacional | AA5: Primeiramente, é válido iniciar esta observação notando que o projeto foi financiado através de uma doação da The Broad Reach Foundation. Isto posto, o relatório tem como objetivo avaliar a política externa dos EUA para com a região do Oriente Médio que passou sucessivas administrações na Casa Branca, os resultados produzidos para a região e/ou para os interesses norte americanos não têm tido saldo positivo. Bem como, este salienta que após anos de intervenções na região, a mesma continua mergulhada na instabilidade que afeta os interesses estadunidenses. Além disso, o trabalho se inicia com a seguinte pergunta: “é hora de repensar algumas das premissas fundamentais subjacentes à formulação de políticas dos EUA nesta região?”. A partir disso, o relatório tem como base a avaliação das vantagens e dos trade-offs de “uma estratégia regional alternativa na qual os objetivos estratégicos se ligam a uma compreensão mais ampla da estabilidade que prioriza a redução de conflitos, melhor governança, e maior crescimento e desenvolvimento”. Ainda, foi possível a observância de uma certa preocupação com o Irã. Como também, destaca que “devido a pandemia, mudanças climáticas e perturbações nos mercados petrolíferos - combinadas com os múltiplos conflitos e falhas de governança da região - a estratégia dos EUA não podem mais se dar ao luxo de se concentrar no nível do estado e da liderança, negligenciando os males da sociedade e da população da região”. Em resumo, ao finalizar o relatório, os pesquisadores apontam algumas recomendações para um redirecionamento nos objetivos estratégicos dos EUA. | AB5: Yasmim | AD5: 4 | AE5: =VLOOKUP(F5,Stakeholders!E:K,7,0) -> 20 | AF5: =VLOOKUP(B5&D5,Areas!$D:$E,2,FALSE) -> #N/A | AH5: 1 - Projeto Prospecta Parte 02 - 2022 | AI5: =COUNTIF(Stakeholders!$E$2:$E$114,F5) -> 1
A6: 2018 | B6: América do Norte | C6: EUA | D6: Global | E6: EUA | F6: RAND Corporation | G6: =COUNTIF(Stakeholders!$E$2:$E960,F6) -> 1 | H6: Discontinuities and Distractions - Rethinking Security for the Year 2040 | I6: https://www.rand.org/pubs/conf_proceedings/CF384.html | J6: sim | K6: sim | W6: não | AB6: Yasmim | AD6: 5 | AE6: =VLOOKUP(F6,Stakeholders!E:K,7,0) -> 20 | AF6: =VLOOKUP(B6&D6,Areas!$D:$E,2,FALSE) -> 283 | AH6: 1 - Projeto Prospecta Parte 02 - 2022 | AI6: =COUNTIF(Stakeholders!$E$2:$E$114,F6) -> 1
A7: 2021 | B7: América do Norte | C7: Israel | D7: Oriente Médio | E7: EUA | F7: Middle East Institute | G7: =COUNTIF(Stakeholders!$E$2:$E960,F7) -> 1 | H7: What will the Middle East Look Like in 2030? An Israeli Perspective | I7: https://www.mei.edu/sites/default/files/2021-02/%20What%20will%20the%20Middle%20East%20look%20like%20in%202030%3F%20An%20Israeli%20Perspective.pdf | J7: sim | K7: sim | W7: sim | AB7: Yasmim | AD7: 6 | AE7: =VLOOKUP(F7,Stakeholders!E:K,7,0) -> 28 | AF7: =VLOOKUP(B7&D7,Areas!$D:$E,2,FALSE) -> #N/A | AH7: 1 - Projeto Prospecta Parte 02 - 2022 | AI7: =COUNTIF(Stakeholders!$E$2:$E$114,F7) -> 1
A8: 2020 | B8: América do Norte | C8: EUA | D8: EUA - China | E8: EUA | F8: Center for Strategic & International Studies (CSIS) | G8: =COUNTIF(Stakeholders!$E$2:$E960,F8) -> 1 | H8: Four Scenarios for Geopolitical Order in 2025-2030: What Will Great Power Competition Look Like? | I8: https://www.csis.org/analysis/four-scenarios-geopolitical-order-2025-2030-what-will-great-power-competition-look | J8: sim | K8: sim | L8: sim | M8: sim | N8: não | O8: sim | P8: não | Q8: não | R8: sim | S8: sim | T8: sim | U8: não | W8: sim | X8: Geopolítica | Y8: Influência Global | Z8: Relação bilateral | AB8: Yasmim | AD8: 7 | AE8: =VLOOKUP(F8,Stakeholders!E:K,7,0) -> 17 | AF8: =VLOOKUP(B8&D8,Areas!$D:$E,2,FALSE) -> #N/A | AH8: 1 - Projeto Prospecta Parte 02 - 2022 | AI8: =COUNTIF(Stakeholders!$E$2:$E$114,F8) -> 1
A9: 2015 | B9: América do Norte | C9: EUA | D9: Ásia - Pacífico | E9: EUA | F9: Center for Strategic & International Studies (CSIS) | G9: =COUNTIF(Stakeholders!$E$2:$E960,F9) -> 1 | H9: Defense 2045: Assessing the Future Security Environment and Implications for Defense Policymakers | I9: https://csis-website-prod.s3.amazonaws.com/s3fs-public/legacy_files/files/publication/151106_Miller_Defense2045_Web.pdf | J9: sim | K9: não | W9: sim | AB9: Yasmim | AD9: 8 | AE9: =VLOOKUP(F9,Stakeholders!E:K,7,0) -> 17 | AF9: =VLOOKUP(B9&D9,Areas!$D:$E,2,FALSE) -> #N/A | AH9: 1 - Projeto Prospecta Parte 02 - 2022 | AI9: =COUNTIF(Stakeholders!$E$2:$E$114,F9) -> 1
A10: 2018 | B10: América Central | C10: Honduras | D10: Honduras | E10: Honduras | F10: Facultad de Ciencias Espaciales | G10: =COUNTIF(Stakeholders!$E$2:$E960,F10) -> 1 | H10: Proyeccción de operaciones aéreas al año 2030 aeródromo de Tela, Atlántida, Honduras | I10: https://www.lamjol.info/index.php/CE/article/view/7170/6735 | J10: sim | K10: sim | W10: não | AB10: Yasmim | AD10: 9 | AE10: =VLOOKUP(F10,Stakeholders!E:K,7,0) -> 6 | AF10: =VLOOKUP(B10&D10,Areas!$D:$E,2,FALSE) -> 71 | AH10: 1 - Projeto Prospecta Parte 02 - 2022 | AI10: =COUNTIF(Stakeholders!$E$2:$E$114,F10) -> 1
A11: 2020 | B11: Organismo Internacional | C11: Sem país específico | D11: Não se aplica | E11: International Renewable Energy Agency | F11: International Renewable Energy Agency | G11: =COUNTIF(Stakeholders!$E$2:$E960,F11) -> 1 | H11: Global Renewables Outlook: Energy Transformation 2050 | I11: https://www.irena.org/-/media/Files/IRENA/Agency/Publication/2020/Apr/IRENA_Global_Renewables_Outlook_2020.pdf | J11: não | K11: sim | W11: não | AB11: Yasmim | AD11: 10 | AE11: =VLOOKUP(F11,Stakeholders!E:K,7,0) -> 105 | AF11: =VLOOKUP(B11&D11,Areas!$D:$E,2,FALSE) -> #N/A | AH11: 1 - Projeto Prospecta Parte 02 - 2022 | AI11: =COUNTIF(Stakeholders!$E$2:$E$114,F11) -> 1
A12: 2019 | B12: América do Norte | C12: EUA | D12: China | E12: EUA | F12: The brookings Africa Growth Initiative | G12: =COUNTIF(Stakeholders!$E$2:$E960,F12) -> 1 | H12: The US-China Nuclear Relationship: why competition is likely to intensify | I12: https://www.brookings.edu/wp-content/uploads/2019/09/FP_20190930_china_nuclear_weapons_talmadge-2.pdf | J12: sim | K12: sim | L12: sim | M12: não | N12: não | O12: sim | P12: não | Q12: não | R12: sim | S12: sim | T12: sim | U12: sim | W12: não | X12: Arsenal nuclear | Y12: US-China | Z12: Mutually Assured Destruction (MAD) | AA12: O relatório se inicia realizando um pequeno panorama sobre como as armas nucleares têm se expandindo nas relações periféricas entre EUA-China. Além disso, a preocupação dos EUA é fazer com que a China fique preocupada, caso esta se engaje em um conflito de escalada nuclear, uma vez que na perspectiva estadunidense, os EUA estaria mais propenso a suportar os riscos que seriam ocasionados do que a China. Visto que, esta última teria capacidade menor quando comparada com os EUA que dotaria de vantagens de barganha para com a China, caso uma guerra eclodisse. O documento analisado nos elucida sobre a deterioração da relação entre EUA-China aumentou a preocupação com as possíveis consequências da intensificação militar entre esses dois Estados. Apesar de alguns analistas enfatizarem que o conflito está longe de ser inevitável, outros analistas observam que há uma possibilidade crescente de os conflitos ou até mesmo guerra possam ocorrer nos mares do Leste ou do Sul da China, ou sobre Taiwan. nalisando pela perspectiva Chinesa, o país “está buscando uma capacidade de second-strike capability (capacidade de segundo ataque) mais seguro - uma força que possa garantir um nível inaceitável de retaliação nuclear contra qualquer estado que lance um primeiro ataque contra a China, e assim impedir que tal ataque seja lançado”. (p. 2). Todavia, esta movimentação Chinesa que não é considerada como nova, está preocupando Washington à medida que durante a administração Obama, os EUA evitam descrever a relação nuclear como uma relação de destruição mútua assegurada (MAD - Mutual Assured Destruction). O MAD pressupõe que não há uma prerrogativa que evite que ambos os lados sofram com os danos, não importando quem ataque primeiro. Em suma, o documento irá demonstrar como os formuladores de políticas estadunidenses poderiam gerenciar uma relação nuclear mais competitiva. | AB12: Yasmim | AD12: 11 | AE12: =VLOOKUP(F12,Stakeholders!E:K,7,0) -> 30 | AF12: =VLOOKUP(B12&D12,Areas!$D:$E,2,FALSE) -> #N/A | AH12: 1 - Projeto Prospecta Parte 02 - 2022 | AI12: =COUNTIF(Stakeholders!$E$2:$E$114,F12) -> 1
A13: 2020 | B13: América do Norte | C13: EUA | D13: Global | E13: EUA | F13: Center for Global Development | G13: =COUNTIF(Stakeholders!$E$2:$E960,F13) -> 1 | H13: Horizon 2025 - End of the Beginning; Development Cooperation in the Pandemic Age | I13: https://www.cgdev.org/sites/default/files/horizon-2025-end-beginning-development-cooperation-pandemic-age.pdf | J13: não | K13: sim | W13: não | AB13: Yasmim | AD13: 12 | AE13: =VLOOKUP(F13,Stakeholders!E:K,7,0) -> 15 | AF13: =VLOOKUP(B13&D13,Areas!$D:$E,2,FALSE) -> 283 | AH13: 1 - Projeto Prospecta Parte 02 - 2022 | AI13: =COUNTIF(Stakeholders!$E$2:$E$114,F13) -> 1
A14: 2017 | B14: América do Norte | C14: EUA | D14: Global | E14: EUA | F14: The brookings Africa Growth Initiative | G14: =COUNTIF(Stakeholders!$E$2:$E960,F14) -> 1 | H14: Securing Global Cities - Best practices, innovation, and the path ahead | I14: https://www.brookings.edu/research/securing-global-cities-2/ | J14: não | K14: sim | W14: não | AB14: Yasmim | AD14: 13 | AE14: =VLOOKUP(F14,Stakeholders!E:K,7,0) -> 30 | AF14: =VLOOKUP(B14&D14,Areas!$D:$E,2,FALSE) -> 283 | AH14: 1 - Projeto Prospecta Parte 02 - 2022 | AI14: =COUNTIF(Stakeholders!$E$2:$E$114,F14) -> 1
A15: 2020 | B15: América do Norte | C15: México | D15: México | E15: México | F15: Revista del Centro de Estudios Superiores Navales | G15: =COUNTIF(Stakeholders!$E$2:$E960,F15) -> 1 | H15: Planteamientos para el desarrollo de la Estrategia Marítima 2020 - 2040 - Revista de Centro de Estudios Superiores Navales, México, 2020, Vol. 41 Núm. 1 Enemar, pág 187 - 229. | I15: https://cesnav.uninav.edu.mx/cesnav/revista_pdf/2020/2020-1.pdf | J15: sim | AB15: Yasmim | AD15: 14 | AE15: =VLOOKUP(F15,Stakeholders!E:K,7,0) -> 35 | AF15: =VLOOKUP(B15&D15,Areas!$D:$E,2,FALSE) -> 106 | AH15: 1 - Projeto Prospecta Parte 02 - 2022 | AI15: =COUNTIF(Stakeholders!$E$2:$E$114,F15) -> 1
A16: 2019 | B16: América do Norte | C16: México | D16: México | E16: México | F16: Revista del Centro de Estudios Superiores Navales | G16: =COUNTIF(Stakeholders!$E$2:$E960,F16) -> 1 | H16: Desafíos a las Estrategias de Ciberseguridad en América - Revista de Centro de Estudios Superiores Navales, México, 2019 Vol. 40 Núm. 4. 4oct-Dic, pág. 25 - 53 | I16: https://cesnav.uninav.edu.mx/cesnav/revista_pdf/2019/2019-4.pdf | J16: sim | AB16: Yasmim | AD16: 15 | AE16: =VLOOKUP(F16,Stakeholders!E:K,7,0) -> 35 | AF16: =VLOOKUP(B16&D16,Areas!$D:$E,2,FALSE) -> 106 | AH16: 1 - Projeto Prospecta Parte 02 - 2022 | AI16: =COUNTIF(Stakeholders!$E$2:$E$114,F16) -> 1
A17: 2012 | B17: América do Norte | C17: EUA | D17: EUA | E17: EUA | F17: Federal Emergency Management Agency | G17: =COUNTIF(Stakeholders!$E$2:$E960,F17) -> 1 | H17: Crisis Reposnse and Disaster Resilience 2030: Forging Strategic Action in an Age of Uncertainty | I17: https://fas.org/irp/agency/dhs/fema/crisis.pdf | J17: não | K17: sim | W17: não | AB17: Yasmim | AD17: 16 | AE17: =VLOOKUP(F17,Stakeholders!E:K,7,0) -> 33 | AF17: =VLOOKUP(B17&D17,Areas!$D:$E,2,FALSE) -> 56 | AH17: 1 - Projeto Prospecta Parte 02 - 2022 | AI17: =COUNTIF(Stakeholders!$E$2:$E$114,F17) -> 1
A18: 2020 | B18: América do Norte | C18: Canadá | D18: Canadá | E18: Canadá | F18: Policy Horizons Canada | G18: =COUNTIF(Stakeholders!$E$2:$E960,F18) -> 1 | H18: Foresight on Covid-19 - Possible shifts and implications | I18: https://horizons.gc.ca/en/2021/03/05/foresight-on-covid-19-possible-shifts-and-implications/ | J18: não | AB18: Yasmim | AD18: 17 | AE18: =VLOOKUP(F18,Stakeholders!E:K,7,0) -> 13 | AF18: =VLOOKUP(B18&D18,Areas!$D:$E,2,FALSE) -> 80 | AH18: 1 - Projeto Prospecta Parte 02 - 2022 | AI18: =COUNTIF(Stakeholders!$E$2:$E$114,F18) -> 1
A19: 2017 | B19: América do Norte | C19: Canadá | D19: Canadá | E19: Canadá | F19: Canadian Army | G19: =COUNTIF(Stakeholders!$E$2:$E960,F19) -> 1 | H19: Alternate Worlds and Implocations, Vol. 3 | I19: http://publications.gc.ca/collections/collection_2018/mdn-dnd/D2-354-3-2017-eng.pdf | AB19: Yasmim | AD19: 18 | AE19: =VLOOKUP(F19,Stakeholders!E:K,7,0) -> 12 | AF19: =VLOOKUP(B19&D19,Areas!$D:$E,2,FALSE) -> 80 | AH19: 1 - Projeto Prospecta Parte 02 - 2022 | AI19: =COUNTIF(Stakeholders!$E$2:$E$114,F19) -> 1
A20: 2020 | B20: América do Norte | C20: EUA | D20: Global | E20: EUA | F20: Atlantic Council | G20: =COUNTIF(Stakeholders!$E$2:$E960,F20) -> 1 | H20: What World Post-Covid-19? Three Scenarios | I20: https://www.atlanticcouncil.org/content-series/shaping-post-covid-world-together/what-world-post-covid-19-three-scenarios/ | J20: não | K20: sim | L20: sim | M20: não | N20: não | O20: não | P20: não | Q20: não | R20: não | S20: não | T20: não | U20: não | W20: não | X20: Balança de poder | Y20: geopolítica | AA20: Apesar de dedicar a pergunta do título à COVID-19 (what world post-covid-19?), não se deve deixar enganar: o “mundo pós-covid” é apenas o ponto de partida dos cenários. O relatório até considera a influência da COVID, mas com o mesmo grau de importância que dá a quaisquer outras questões como commodities, desastre humanitário, dentre outros. Na verdade, o ponto fundamental deste estudo é a mudança do equilíbrio geopolítico do mundo (com preocupação especial voltada à China), abordando superficialmente para impactos originados de questões econômicas e sociais. Há um trecho dedicado à América Latina. A avaliação geral é a de que a região está fragilizada por conta 1) dos impactos da covid e 2) por depender majoritariamente dos ciclos de commodities, mais especificamente o petróleo. Por isso, o relatório diz que , apesar de a região não ser um campo de disputa competitivo entre EUA e China, os EUA devem se preocupar com a tentativa de inserção da China na região através de auxílio para recuperação econômica. Os 3 cenários 1 Acelerando para baixo: “a desglobalização está se acelerando, produzindo um crescimento econômico lento em todos os lugares. Os níveis de pobreza estão aumentando no mundo em desenvolvimento e há potencial para um conflito aberto entre os Estados Unidos e uma aliança China-Rússia.” 2 China primeiro: “Para muitos países fora da Europa, os Estados Unidos aparecem em declínio acentuado. Apesar da responsabilidade da China pelo surto, a pandemia inclinou a balança geopolítica a seu favor.” 3 nova renascença: "Com a redução das tensões interestaduais, o crescimento econômico é retomado e, para a maioria da população mundial, os Objetivos de Desenvolvimento Sustentável de eliminação da pobreza e disseminação da educação estão mais uma vez ao alcance." | AB20: Yasmim | AD20: 19 | AE20: =VLOOKUP(F20,Stakeholders!E:K,7,0) -> 32 | AF20: =VLOOKUP(B20&D20,Areas!$D:$E,2,FALSE) -> 283 | AH20: 1 - Projeto Prospecta Parte 02 - 2022 | AI20: =COUNTIF(Stakeholders!$E$2:$E$114,F20) -> 1
A21: 2019 | B21: América do Norte | C21: EUA | D21: Global | E21: EUA | F21: Atlantic Council | G21: =COUNTIF(Stakeholders!$E$2:$E960,F21) -> 1 | H21: Global risks 2035 update: Decline or new renaissance? | I21: https://www.atlanticcouncil.org/in-depth-research-reports/report/global-risks-2035-update/ | J21: sim | K21: sim | W21: não | AB21: Yasmim | AD21: 20 | AE21: =VLOOKUP(F21,Stakeholders!E:K,7,0) -> 32 | AF21: =VLOOKUP(B21&D21,Areas!$D:$E,2,FALSE) -> 283 | AH21: 1 - Projeto Prospecta Parte 02 - 2022 | AI21: =COUNTIF(Stakeholders!$E$2:$E$114,F21) -> 1
A22: 2016 | B22: América do Norte | C22: EUA | D22: América Latina/ Caribe | E22: EUA | F22: Atlantic Council | G22: =COUNTIF(Stakeholders!$E$2:$E960,F22) -> 1 | H22: Latin America and the Caribbean 2030: futures scenarios | I22: https://www.atlanticcouncil.org/in-depth-research-reports/report/latin-america-and-the-caribbean-2030-future-scenarios/ | J22: não | K22: sim | W22: não | AB22: Yasmim | AD22: 21 | AE22: =VLOOKUP(F22,Stakeholders!E:K,7,0) -> 32 | AF22: =VLOOKUP(B22&D22,Areas!$D:$E,2,FALSE) -> #N/A | AH22: 1 - Projeto Prospecta Parte 02 - 2022 | AI22: =COUNTIF(Stakeholders!$E$2:$E$114,F22) -> 1
A23: 2019 | B23: América do Norte | C23: Canadá | D23: Global | E23: Canadá | F23: Canadian Network for Defence and Security Analysis | G23: =COUNTIF(Stakeholders!$E$2:$E960,F23) -> 1 | H23: Foresight & Analysis: In Canadian Defense and Security Policy | I23: https://www.balsillieschool.ca/wp-content/uploads/2019/02/CNDSA-Report-2019.pdf | J23: sim | K23: não | L23: sim | M23: não | N23: não | O23: sim | P23: não | Q23: não | R23: sim | S23: sim | T23: não | U23: não | W23: não | X23: segurança/defesa | Y23: geopilítica | Z23: Canadá | AA23: O relatóro fala majoritáriamente sobre como o Canadá deve se portar – sob o aspecto da segurança e defesa – frente ao cenário geopolítcio onde estão inseridos. Relatam alguma preocupação com terrorismos, mas apresentam maiores dados sobre suas questões com a Rússia e a China, além de preocupação com sa segurança cibernética (por isso foi sinalizado com sim o campo tecnológico). O aspecto militar é recorrentemente mecionado, com a sugestão de aquiseção de novos equipamentos, sobretudo para a marinha, o que levou a marcar os campos militar e marítimo nesta planilha. Ainda assim o texto não se aprfunda nestes aspectos. Apesar do relatório abordar brevemente a possibilidade de problemas futuros, como embates no Mar do Sul da China, disputas pesqueiras e também a respeito dos interesses canadenses no Ártico ( e possíveis dificuldades que possam advir neste campo), não pareceu trazer nenhum aspecto novo que indique qualquer semente de futuro. | AB23: Yasmim | AD23: 22 | AE23: =VLOOKUP(F23,Stakeholders!E:K,7,0) -> 10 | AF23: =VLOOKUP(B23&D23,Areas!$D:$E,2,FALSE) -> 283 | AH23: 1 - Projeto Prospecta Parte 02 - 2022 | AI23: =COUNTIF(Stakeholders!$E$2:$E$114,F23) -> 1
A24: 2020 | B24: América do Norte | C24: EUA | D24: EUA | E24: EUA | F24: RAND Corporation | G24: =COUNTIF(Stakeholders!$E$2:$E960,F24) -> 1 | H24: Developing New Futures Scenarios for the U.S. Coast Guard's Evergreen Strategic Foresight Program | I24: https://www.rand.org/pubs/research_reports/RR3147.html | J24: sim | K24: não | W24: sim | AB24: Yasmim | AC24: 44315 | AD24: 23 | AE24: =VLOOKUP(F24,Stakeholders!E:K,7,0) -> 20 | AF24: =VLOOKUP(B24&D24,Areas!$D:$E,2,FALSE) -> 56 | AH24: 1 - Projeto Prospecta Parte 02 - 2022 | AI24: =COUNTIF(Stakeholders!$E$2:$E$114,F24) -> 1
A25: 2020 | B25: América do Norte | C25: EUA | D25: Global | E25: EUA | F25: Center for Strategic & International Studies (CSIS) | G25: =COUNTIF(Stakeholders!$E$2:$E960,F25) -> 1 | H25: Global Security Forum 2020: A New Era for U.S. Alliances | I25: https://www.csis.org/analysis/global-security-forum-2020-new-era-us-alliances | J25: sim | K25: sim | L25: sim | M25: sim | N25: não | O25: sim | P25: sim | Q25: não | R25: sim | S25: sim | T25: sim | U25: sim | W25: não | X25: Sistema de aliança | Y25: Influência global | Z25: Indo-Pacífico | AA25: O relatório de análise inicia sua análise já evidenciando as preocupações atreladas aos EUA e seus aliados e como estes estão “minados” pela ascensão de outros atores, tal como Rússia e China. A Rússia pela anexação da Crimeia e a China pela expansão coercitiva no Mar do Sul da China. Além disso, o relatório foi produzido observando a transição entre a administração Trump para a administração de Biden e tendo isso como ponto de análise, foi pontuado que o sistema de alianças é muito mais importante nos dias de hoje como nunca foi antes. Ainda, eles notaram que dentro do “guarda-chuva” de responsabilidades empreendidas pelos EUA estão: a estabilidade econômica, não proliferação, contenção do terrorismo e a prevenção de conflito violento em larga escala. Com isso, os EUA possuem o desafio, na concepção do autor deste relatório, de gerir a pandemia da COVID-19, enquanto revigora o poder dos valores norte-americanos na competição com o crescimento coercitivo da China. 3 CENÁRIOS SÃO PROJETADOS NESSE RELATÓRIO, SÃO ELES: 1- TAIWAN 2025 → A República Popular da China Bloqueia Taiwan e usa seu poderio militar e econômico para impedir uma resposta global; 2 - CRISE CLIMÁTICA 2030 → O mundo sofre com várias catástrofes relacionadas ao clima que estão em andamento e que provocam insegurança alimentar*, migração em massa e desafios de segurança nas fronteiras; * A insegurança alimentar pode ser pensada aqui também, como no grupo de Biodefesa e Benchmarking, como uma ferramenta de conflito, visto que países já o enfrentam. 3 - RÚSSIA 2024 → A interferência russa nas eleições estadunidenses leva a uma escalada do conflito cibernético e espacial com os EUA, que ameaça se alastrar (spill over) para o conflito armado. Há uma observância de 4 temas transversais associados que podem auxiliar no fortalecimento das alianças, são eles: alianças começando do zero; As ameaças no século 21 são regional e global; as ameaças hoje ocorrem na interseção da preocupação militar, diplomática e econômica; e, por último as alianças dependem do compartilhamento do entendimento e sacrifício. | AB25: Yasmim | AC25: 44315 | AD25: 24 | AE25: =VLOOKUP(F25,Stakeholders!E:K,7,0) -> 17 | AF25: =VLOOKUP(B25&D25,Areas!$D:$E,2,FALSE) -> 283 | AH25: 1 - Projeto Prospecta Parte 02 - 2022 | AI25: =COUNTIF(Stakeholders!$E$2:$E$114,F25) -> 1
A26: 2020 | B26: América do Norte | C26: EUA | D26: Global | E26: EUA | F26: House Armed Service Committee | G26: =COUNTIF(Stakeholders!$E$2:$E960,F26) -> 1 | H26: Future od Defense Task Force - Report 2020 | I26: https://armedservices.house.gov/_cache/files/2/6/26129500-d208-47ba-a9f7-25a8f82828b0/424EB2008281A3C79BA8C7EA71890AE9.future-of-defense-task-force-report.pdf | AB26: Yasmim | AD26: 25 | AE26: =VLOOKUP(F26,Stakeholders!E:K,7,0) -> 26 | AF26: =VLOOKUP(B26&D26,Areas!$D:$E,2,FALSE) -> 283 | AH26: 1 - Projeto Prospecta Parte 02 - 2022 | AI26: =COUNTIF(Stakeholders!$E$2:$E$114,F26) -> 1
A27: 2020 | B27: América do Norte | C27: EUA | D27: Região do Ártico | E27: EUA | F27: Center for Strategic & International Studies (CSIS) | G27: =COUNTIF(Stakeholders!$E$2:$E960,F27) -> 1 | H27: America's Arctic Moment: Great Power Competition in the Arctic to 2050 | I27: https://www.csis.org/analysis/americas-arctic-moment-great-power-competition-arctic-2050 | J27: sim | K27: sim | W27: não | AB27: Yasmim | AC27: 44315 | AD27: 26 | AE27: =VLOOKUP(F27,Stakeholders!E:K,7,0) -> 17 | AF27: =VLOOKUP(B27&D27,Areas!$D:$E,2,FALSE) -> #N/A | AH27: 1 - Projeto Prospecta Parte 02 - 2022 | AI27: =COUNTIF(Stakeholders!$E$2:$E$114,F27) -> 1
A28: 2020 | B28: América do Norte | C28: EUA | D28: Global | E28: EUA | F28: Rand Corporation | G28: =COUNTIF(Stakeholders!$E$2:$E960,F28) -> 1 | H28: The Future of Warfare in 2030 - Project Overview and Conclusions | I28: https://www.rand.org/pubs/research_reports/RR2849z1.html | J28: sim | K28: sim | L28: sim | M28: sim | N28: sim | O28: sim | P28: sim | Q28: sim | R28: sim | S28: não | T28: sim | U28: não | W28: não | X28: Guerra Futura | Y28: Terrorismo | Z28: Oriente Médio | AA28: As escolhas desses termos chaves se deu pela abordagem do relatório sobre as preocupações estadunidesentes para como será as guerra futuras e seus principais atores e localidade. Para mais, é notável que o terrorismo é um dos fatores que mais preocupam os norte americanos e estes observam o Oriente Médio como Lócus de grupos não estatais para proliferação desses grupos. | AB28: Yasmim | AC28: 44315 | AD28: 27 | AE28: =VLOOKUP(F28,Stakeholders!E:K,7,0) -> 20 | AF28: =VLOOKUP(B28&D28,Areas!$D:$E,2,FALSE) -> 283 | AH28: 1 - Projeto Prospecta Parte 02 - 2022 | AI28: =COUNTIF(Stakeholders!$E$2:$E$114,F28) -> 1
A29: 2020 | B29: América do Norte | C29: EUA | D29: Global | E29: EUA | F29: Rand Corporation | G29: =COUNTIF(Stakeholders!$E$2:$E960,F29) -> 1 | H29: Measuring Power, Power Cycles, and the Risk of Great-Power War in the 21st Century | I29: https://www.rand.org/pubs/research_reports/RR2989.html | J29: sim | K29: sim | L29: sim | M29: sim | N29: não | O29: sim | P29: sim | Q29: não | R29: sim | S29: nao | T29: sim | U29: não | W29: não | X29: Terrorismo | Y29: Balança de poder | Z29: Power Cycle Theory | AA29: Estes termos foram pontuados como chaves devido a preocupação dentro de um cenário com horizonte para 2040, temas como o terrorismo, a balança de poder e a mundança climática são fatores fortes que podem impactar na reestruturação do Sistema Internacional, segundo o relatório analisado, cabendo ressaltar que há outros fatores que são pontuados na análise. Por fim, a Power Cycle Theory foi considerada termo chave devido esta ter sido a metodologia principal de análise para mensuração da balança de poder. | AB29: Yasmim | AC29: 44315 | AD29: 28 | AE29: =VLOOKUP(F29,Stakeholders!E:K,7,0) -> 20 | AF29: =VLOOKUP(B29&D29,Areas!$D:$E,2,FALSE) -> 283 | AH29: 1 - Projeto Prospecta Parte 02 - 2022 | AI29: =COUNTIF(Stakeholders!$E$2:$E$114,F29) -> 1
A30: 2020 | B30: América do Norte | C30: EUA | D30: Global | E30: EUA | F30: Air Force Warfighting Integration Capability | G30: =COUNTIF(Stakeholders!$E$2:$E960,F30) -> 1 | H30: Global Futures Reports: Alternative Futures of Geopolitical Competition in a Post-Covid-19 World | I30: https://apps.dtic.mil/sti/citations/AD1108029 | J30: sim | K30: sim | L30: sim | M30: não | N30: sim | O30: sim | P30: não | Q30: não | R30: sim | S30: não | T30: não | U30: sim | V30: competição geopolítica | W30: sim | X30: geopolítica espacial | Y30: cadeia de suprimentos | Z30: sistemas autônomos | AA30: O relatório compila uma série de análises feitas por diversos especialistas, que abordam temas que vão desde métodos para estudos de futuros até tendências, especialmente com relação à competição geopolítica do mundo pós covid COVID-19. Por ser um documento elaborado pela força aérea dos EUA, a análise tem foco nos assuntos mais afetos às questões aero espaciais. Com relação a métodos, o relatório apresenta o “four futures method”, também chamado de “manoa school method”, que é semelhante ao que conhecemos como “eixos ortogonais”, mas obrigatoriamente considera um cenário de colapso, um de crescimento, um de transformação e um disciplinado. Com relação às tendências, elas focam no aspecto geopolítico, mas também perpassam temas que envolvem cybertecnologia e competição espacial, cadeia de suprimentos e campanhas políticas nocivas. Os 4 cenários vislumbrados no relatório são: Transformação: FROM BIO-HEGEMONY TO BIO-SUPREMACY Colapso: THE NEW WARRING STATES PERIOD Disciplina: AUTHORITARIAN REGIONALISM Crescimento: ENDEMIC DISRUPTION | AB30: Yasmim | AC30: 44323 | AD30: 29 | AE30: =VLOOKUP(F30,Stakeholders!E:K,7,0) -> 19 | AF30: =VLOOKUP(B30&D30,Areas!$D:$E,2,FALSE) -> 283 | AH30: 1 - Projeto Prospecta Parte 02 - 2022 | AI30: =COUNTIF(Stakeholders!$E$2:$E$114,F30) -> 1
A31: 2021 | B31: América do Norte | C31: EUA | D31: Global | E31: EUA | F31: National intelligence council | G31: =COUNTIF(Stakeholders!$E$2:$E960,F31) -> 1 | H31: Global Trends 2040 - A More Contested World | I31: https://www.dni.gov/files/images/globalTrends/GT2040/GlobalTrends_2040_for_web1.pdf | J31: não | K31: sim | W31: não | AB31: Yasmim | AC31: 44327 | AD31: 30 | AE31: =VLOOKUP(F31,Stakeholders!E:K,7,0) -> 21 | AF31: =VLOOKUP(B31&D31,Areas!$D:$E,2,FALSE) -> 283 | AH31: 1 - Projeto Prospecta Parte 02 - 2022 | AI31: =COUNTIF(Stakeholders!$E$2:$E$114,F31) -> 1
A32: 2020 | B32: América do Norte | C32: EUA | D32: Oriente Médio | E32: EUA | F32: Middle East Institute | G32: =COUNTIF(Stakeholders!$E$2:$E960,F32) -> 1 | H32: Middle East Conflict and COVID-19 - A View from 2025. | I32: https://www.mei.edu/publications/middle-east-conflict-and-covid-19-view-2025 | J32: não | K32: sim | L32: não | M32: sim | N32: sim | O32: não | P32: não | Q32: não | R32: não | S32: não | T32: não | U32: não | W32: não | X32: Impactos da covid | Y32: Crescimento econômico | Z32: mortalidade | AA32: O relatório apresenta dois produtos: 1. Cenários a respeito dos impactos da COVID-19 África. 2. Uma comparação com um cenário pré-covid (uma projeção feita pelo FMI em outubro de 2019) Esses produtos, por sua vez, possibilitaram a sugestão de políticas públicas para reduzir a fragilidade da África perante a COVID. O relatório passa pelo método de maneira superficial e indireta. Em alguns momentos é possível apreender os processos metodológicos utilizados no estudo, que vão sendo descritos de maneira fracionada ao longo do relatório, na medida em que vão sendo utiliuzados. Contudo, o método e as ferramentas utilizados para a construção dos cenários não é descrito e maneira detalhada. Como o estudo tem como base a projeção do FMI, que leva em considerações aspectos econômicos, o relatório segue a mesma linha, e foca sua atenção no crescimento econômico. Adicionalmente, o relatório também considera o impacto social por conta da mortalidade causada pelo vírus. | AB32: Yasmim | AC32: 44334 | AD32: 31 | AE32: =VLOOKUP(F32,Stakeholders!E:K,7,0) -> 28 | AF32: =VLOOKUP(B32&D32,Areas!$D:$E,2,FALSE) -> #N/A | AH32: 1 - Projeto Prospecta Parte 02 - 2022 | AI32: =COUNTIF(Stakeholders!$E$2:$E$114,F32) -> 1
A33: 2018 | B33: América do Norte | C33: EUA | D33: Oriente Médio | E33: EUA | F33: The brookings | G33: =COUNTIF(Stakeholders!$E$2:$E960,F33) -> 1 | H33: Forecasting change in militaru technology, 2020-2040 | I33: https://www.brookings.edu/research/forecasting-change-in-military-technology-2020-2040/ | J33: sim | K33: sim | W33: não | AB33: Yasmim | AC33: 44372 | AD33: 32 | AE33: =VLOOKUP(F33,Stakeholders!E:K,7,0) -> 31 | AF33: =VLOOKUP(B33&D33,Areas!$D:$E,2,FALSE) -> #N/A | AH33: 1 - Projeto Prospecta Parte 02 - 2022 | AI33: =COUNTIF(Stakeholders!$E$2:$E$114,F33) -> 1
A34: 2020 | B34: Europa | C34: Noruega | D34: Noruega | E34: Noruega | F34: Norwegian Ministry of defence | G34: =COUNTIF(Stakeholders!$E$2:$E960,F34) -> 1 | H34: The defence of Norway: Capability and readiness | I34: https://drive.google.com/file/d/1NNrgO9zaie7enkXDuP15XpbIwCDApvYH/view?usp=drivesdk | J34: sim | K34: não | L34: não | M34: não | N34: não | O34: não | P34: não | Q34: não | R34: sim | S34: não | T34: não | U34: não | W34: não | X34: Noruega | Y34: defesa | AA34: -->Sementes: Ainda que o texto possa trazer um ou outro indício de mudança no cenário geopolítico não apresenta nenhum elemento que possa indicar o acontecimento de tais eventos. Há, contudo, uma cenarização a partir das mudanças esperadas. Este cenário, ainda contempla tanto elementos de alcance global quanto regionais; --> Política/geopolítica: Apesar de falar bastante sobre a situação geopolítica onde a Noruega está inserida, o texto não foca neste aspecto, sendo ele tão somente uma contextualização para o restante do texto; --> Econômico/Social: Apesar do documento expressar diversas vezes a necessidade das FA trabalharem em conjunto com a população civil e da importância desta para a estratégia de defesa e prontidão do país, não há nada que trate especificamente do fator social; --> Tecnológico: o documento traz referências à necessidade do crescente desenvolvimento tecnológico para a segurança do país e também à necessidade da cooperação civil-militar para que se logre tal objetivo. Entretanto, não aprofunda no assunto; —>Militar/Marítimo/Terrestre/Aeroespacial: o texto aborda assuntos militares, porém relacionados às FA norueguesas. Trata muito brevemente dos seus braços (marinha, exército, aeronáutica e forças especiais), onde apresenta objetivamente os objetivos de continuidade, modernização e substituição de alguns de seus meios além da incorporação de novos. Não trata de assuntos correlatos a nenhum dos poderes militares (Marítimo/Terrestre/Aeroespacial). Há entretanto um único apontamento ao poder marítimo, especificamente sobre a importância das linhas de comunicação marítimas no Atlântico no caso de crise ou conflito. | AB34: Laura | AD34: 33 | AE34: =VLOOKUP(F34,Stakeholders!E:K,7,0) -> 79 | AF34: =VLOOKUP(B34&D34,Areas!$D:$E,2,FALSE) -> 225 | AH34: 1 - Projeto Prospecta Parte 02 - 2022 | AI34: =COUNTIF(Stakeholders!$E$2:$E$114,F34) -> 1
A35: 2019 | B35: Europa | C35: Portugal | D35: Portugal | E35: Portugal | F35: Serviço de Informação de Segurança | G35: =COUNTIF(Stakeholders!$E$2:$E960,F35) -> 1 | H35: Relatório Anual de Segurança Interna | I35: https://drive.google.com/file/d/1Nbvycddazj4n2iSMZi1yfPzGcGvQfHgI/view?usp=drivesdk | AB35: Laura | AD35: 34 | AE35: =VLOOKUP(F35,Stakeholders!E:K,7,0) -> 82 | AF35: =VLOOKUP(B35&D35,Areas!$D:$E,2,FALSE) -> 229 | AH35: 1 - Projeto Prospecta Parte 02 - 2022 | AI35: =COUNTIF(Stakeholders!$E$2:$E$114,F35) -> 1
A36: 2015 | B36: Europa | C36: Reino Unido | D36: Reino Unido | E36: Reino Unido | F36: Government of UK | G36: =COUNTIF(Stakeholders!$E$2:$E960,F36) -> 1 | H36: National Security Strategy and Strategic Defence and Security Review 2015 | I36: https://drive.google.com/file/d/1NslfWBcFpm-5Modcur0Abed3t2ZRkVij/view?usp=drivesdk | AB36: Laura | AD36: 35 | AE36: =VLOOKUP(F36,Stakeholders!E:K,7,0) -> 83 | AF36: =VLOOKUP(B36&D36,Areas!$D:$E,2,FALSE) -> 231 | AH36: 1 - Projeto Prospecta Parte 02 - 2022 | AI36: =COUNTIF(Stakeholders!$E$2:$E$114,F36) -> 1
A37: 2012 | B37: Europa | C37: República Tcheca | D37: República Tcheca | E37: República Tcheca | F37: Ministry of Defence of the Czech Republic | G37: =COUNTIF(Stakeholders!$E$2:$E960,F37) -> 1 | H37: The Defence Strategy Of The Czech Republic | I37: https://drive.google.com/file/d/1NgvWDFjTH0oLB-GEgdeJQb5kqXv05uzw/view?usp=drivesdk | AB37: Laura | AD37: 36 | AE37: =VLOOKUP(F37,Stakeholders!E:K,7,0) -> 84 | AF37: =VLOOKUP(B37&D37,Areas!$D:$E,2,FALSE) -> 233 | AH37: 1 - Projeto Prospecta Parte 02 - 2022 | AI37: =COUNTIF(Stakeholders!$E$2:$E$114,F37) -> 1
A38: 2020 | B38: Europa | C38: Romênia | D38: Romênia | E38: Austria | F38: ETH Zurich Center for Security Studies | G38: =COUNTIF(Stakeholders!$E$2:$E960,F38) -> 1 | H38: Romania's National Cybersecurity and Defense Posture | I38: https://css.ethz.ch/content/dam/ethz/special-interest/gess/cis/center-for-securities-studies/pdfs/Cyber-Reports-2020-10-Romania.pdf | AB38: Laura | AD38: 37 | AE38: =VLOOKUP(F38,Stakeholders!E:K,7,0) -> 65 | AF38: =VLOOKUP(B38&D38,Areas!$D:$E,2,FALSE) -> 235 | AH38: 1 - Projeto Prospecta Parte 02 - 2022 | AI38: =COUNTIF(Stakeholders!$E$2:$E$114,F38) -> 1
A39: 2015 | B39: Europa | C39: Suécia | D39: Suécia | E39: Suécia | F39: Government offices of sweden | G39: =COUNTIF(Stakeholders!$E$2:$E960,F39) -> 1 | H39: Security in a new era | I39: https://drive.google.com/file/d/1NvceA155DVBBp6MD5VOCH2bbX6sy_oLu/view?usp=drivesdk | AB39: Laura | AD39: 38 | AE39: =VLOOKUP(F39,Stakeholders!E:K,7,0) -> 87 | AF39: =VLOOKUP(B39&D39,Areas!$D:$E,2,FALSE) -> 238 | AH39: 1 - Projeto Prospecta Parte 02 - 2022 | AI39: =COUNTIF(Stakeholders!$E$2:$E$114,F39) -> 1
A40: 2009 | B40: Europa | C40: Suíça | D40: Suíça | E40: Austria | F40: ETH Zurich Center for Security Studies | G40: =COUNTIF(Stakeholders!$E$2:$E960,F40) -> 1 | H40: The Swiss Security Policy Report: Key Points and Debates | I40: https://drive.google.com/file/d/1OR1b8-pI0nx6H1kfNIxhfSWtcIcUyiez/view?usp=drivesdk | AB40: Laura | AD40: 39 | AE40: =VLOOKUP(F40,Stakeholders!E:K,7,0) -> 65 | AF40: =VLOOKUP(B40&D40,Areas!$D:$E,2,FALSE) -> 240 | AH40: 1 - Projeto Prospecta Parte 02 - 2022 | AI40: =COUNTIF(Stakeholders!$E$2:$E$114,F40) -> 1
...

Sheet Cálculos
B1: Região | C1: Instituições | D1: Em quantos descobrimos relatórios? | E1: relatórios por países cobertos | F1: países descobertos | G1: Quantos países efetivamente produzem esse tipo de material? | H1: Quantos relatórios descobrimos na região?
B2: África | C2: =SUMIF(Stakeholders!$A$2:$A999,B2,Stakeholders!$D$2:$D999) -> 2 | D2: =SUMIF('calculos 2'!$A$2:$A999,B2,'calculos 2'!$E$2:$E999) -> 26 | E2: =D2/C2 -> 13 | F2: =C2-D2 -> -24 | H2: =SUMIF(Stakeholders!$A$2:$A999,B2,Stakeholders!$J$2:$J999) -> 26 | I2: =COUNTIF(Stakeholders!A:A,B2) -> 2
B3: América Central | C3: =SUMIF(Stakeholders!$A$2:$A999,B3,Stakeholders!$D$2:$D999) -> 2 | D3: =SUMIF('calculos 2'!$A$2:$A999,B3,'calculos 2'!$E$2:$E999) -> 1 | E3: =D3/C3 -> 0.5 | F3: =C3-D3 -> 1 | H3: =SUMIF(Stakeholders!$A$2:$A999,B3,Stakeholders!$J$2:$J999) -> 1 | I3: =COUNTIF(Stakeholders!A:A,B3) -> 2
B4: América do Norte | C4: =SUMIF(Stakeholders!$A$2:$A999,B4,Stakeholders!$D$2:$D999) -> 3.166746 | D4: =SUMIF('calculos 2'!$A$2:$A999,B4,'calculos 2'!$E$2:$E999) -> 104 | E4: =D4/C4 -> 32.841282 | F4: =ABS(C4-D4) -> 100.83325 | H4: =SUMIF(Stakeholders!$A$2:$A999,B4,Stakeholders!$J$2:$J999) -> 103 | I4: =COUNTIF(Stakeholders!A:A,B4) -> 64
B5: América do Sul | C5: =SUMIF(Stakeholders!$A$2:$A999,B5,Stakeholders!$D$2:$D999) -> 1 | D5: =SUMIF('calculos 2'!$A$2:$A999,B5,'calculos 2'!$E$2:$E999) -> 5 | E5: =D5/C5 -> 5 | F5: =C5-D5 -> -4 | H5: =SUMIF(Stakeholders!$A$2:$A999,B5,Stakeholders!$J$2:$J999) -> 5 | I5: =COUNTIF(Stakeholders!A:A,B5) -> 2
B6: Ásia | C6: =SUMIF(Stakeholders!$A$2:$A999,B6,Stakeholders!$D$2:$D999) -> 6.61 | D6: =SUMIF('calculos 2'!$A$2:$A999,B6,'calculos 2'!$E$2:$E999) -> 25 | E6: =D6/C6 -> 3.7821483 | F6: =C6-D6 -> -18.39 | H6: =SUMIF(Stakeholders!$A$2:$A999,B6,Stakeholders!$J$2:$J999) -> 24 | I6: =COUNTIF(Stakeholders!A:A,B6) -> 22
B7: Europa | C7: =SUMIF(Stakeholders!$A$2:$A999,B7,Stakeholders!$D$2:$D999) -> 29.045238 | D7: =SUMIF('calculos 2'!$A$2:$A999,B7,'calculos 2'!$E$2:$E999) -> 82 | E7: =D7/C7 -> 2.8231822 | F7: =C7-D7 -> -52.954762 | H7: =SUMIF(Stakeholders!$A$2:$A999,B7,Stakeholders!$J$2:$J999) -> 89 | I7: =COUNTIF(Stakeholders!A:A,B7) -> 87
B8: Oceania | C8: =SUMIF(Stakeholders!$A$2:$A999,B8,Stakeholders!$D$2:$D999) -> 1.9081818 | D8: =SUMIF('calculos 2'!$A$2:$A999,B8,'calculos 2'!$E$2:$E999) -> 36 | E8: =D8/C8 -> 18.866127 | F8: =C8-D8 -> -34.091818 | H8: =SUMIF(Stakeholders!$A$2:$A999,B8,Stakeholders!$J$2:$J999) -> 35 | I8: =COUNTIF(Stakeholders!A:A,B8) -> 11
B9: Organismo Internacional | C9: =SUMIF(Stakeholders!$A$2:$A999,B9,Stakeholders!$D$2:$D999) -> 9.79 | D9: =SUMIF('calculos 2'!$A$2:$A999,B9,'calculos 2'!$E$2:$E999) -> 16 | E9: =D9/C9 -> 1.6343207 | F9: =C9-D9 -> -6.21 | H9: =SUMIF(Stakeholders!$A$2:$A999,B9,Stakeholders!$J$2:$J999) -> 24 | I9: =COUNTIF(Stakeholders!A:A,B9) -> 18
B10: Total | C10: =SUM(C2:C9) -> 55.520166 | D10: =SUM(D2:D9) -> 295 | E10: =D10/C10 -> 5.3133847 | F10: =C10-D10 -> -239.47983 | H10: =SUM(H2:H9) -> 307 | I10: =SUM(I2:I9) -> 208

Sheet calculos 2
A1: Região | B1: País | C1: Instituições | D1: coluna auxiliar - calculo de países cobertos | E1: Relatórios | F1: d
A2: África | B2: África do Sul | C2: =SUMIF(Stakeholders!$C$2:$C999,B2,Stakeholders!$F$2:$F999) -> 1 | D2: =IF(C2=0,0,1) -> 1 | E2: =SUMIF(Stakeholders!$C$2:$C999,B2,Stakeholders!$J$2:$J999) -> 25
A3: África | B3: Angola | C3: =SUMIF(Stakeholders!$C$2:$C999,B3,Stakeholders!$F$2:$F999) -> 0 | D3: =IF(C3=0,0,1) -> 0 | E3: =SUMIF(Stakeholders!$C$2:$C999,B3,Stakeholders!$J$2:$J999) -> 0
A4: África | B4: Argélia | C4: =SUMIF(Stakeholders!$C$2:$C999,B4,Stakeholders!$F$2:$F999) -> 0 | D4: =IF(C4=0,0,1) -> 0 | E4: =SUMIF(Stakeholders!$C$2:$C999,B4,Stakeholders!$J$2:$J999) -> 0
A5: África | B5: Benim | C5: =SUMIF(Stakeholders!$C$2:$C999,B5,Stakeholders!$F$2:$F999) -> 0 | D5: =IF(C5=0,0,1) -> 0 | E5: =SUMIF(Stakeholders!$C$2:$C999,B5,Stakeholders!$J$2:$J999) -> 0
A6: África | B6: Botswana | C6: =SUMIF(Stakeholders!$C$2:$C999,B6,Stakeholders!$F$2:$F999) -> 0 | D6: =IF(C6=0,0,1) -> 0 | E6: =SUMIF(Stakeholders!$C$2:$C999,B6,Stakeholders!$J$2:$J999) -> 0
A7: África | B7: Burkina Faso | C7: =SUMIF(Stakeholders!$C$2:$C999,B7,Stakeholders!$F$2:$F999) -> 0 | D7: =IF(C7=0,0,1) -> 0 | E7: =SUMIF(Stakeholders!$C$2:$C999,B7,Stakeholders!$J$2:$J999) -> 0
A8: África | B8: Burundi | C8: =SUMIF(Stakeholders!$C$2:$C999,B8,Stakeholders!$F$2:$F999) -> 0 | D8: =IF(C8=0,0,1) -> 0 | E8: =SUMIF(Stakeholders!$C$2:$C999,B8,Stakeholders!$J$2:$J999) -> 0
A9: África | B9: Cabo Verde | C9: =SUMIF(Stakeholders!$C$2:$C999,B9,Stakeholders!$F$2:$F999) -> 0 | D9: =IF(C9=0,0,1) -> 0 | E9: =SUMIF(Stakeholders!$C$2:$C999,B9,Stakeholders!$J$2:$J999) -> 0
A10: África | B10: Camarões | C10: =SUMIF(Stakeholders!$C$2:$C999,B10,Stakeholders!$F$2:$F999) -> 0 | D10: =IF(C10=0,0,1) -> 0 | E10: =SUMIF(Stakeholders!$C$2:$C999,B10,Stakeholders!$J$2:$J999) -> 0
